"""Config flow for Custom Component integration."""
from __future__ import annotations

import voluptuous as vol

from homeassistant import config_entries
from homeassistant.core import HomeAssistant
from homeassistant.data_entry_flow import FlowResult
from homeassistant.exceptions import HomeAssistantError

from .const import DOMAIN

STEP_USER_DATA_SCHEMA = vol.Schema({
    vol.Required("name"): str,
})

async def validate_input(hass: HomeAssistant, data: dict) -> dict:
    """Validate the user input allows us to connect."""
    # TODO: Validate the data can be used to set up the integration
    # If there is an error, raise an exception
    return {"title": data["name"]}

class ConfigFlow(config_entries.ConfigFlow, domain=DOMAIN):
    """Handle a config flow for Custom Component."""

    VERSION = 1

    async def async_step_user(
        self, user_input: dict[str, any] | None = None
    ) -> FlowResult:
        """Handle the initial step."""
        errors = {}
        if user_input is not None:
            try:
                info = await validate_input(self.hass, user_input)
                return self.async_create_entry(title=info["title"], data=user_input)
            except CannotConnect:
                errors["base"] = "cannot_connect"
            except InvalidAuth:
                errors["base"] = "invalid_auth"
            except Exception:  # pylint: disable=broad-except
                errors["base"] = "unknown"

        return self.async_show_form(
            step_id="user", data_schema=STEP_USER_DATA_SCHEMA, errors=errors
        )

class CannotConnect(HomeAssistantError):
    """Error to indicate we cannot connect."""

class InvalidAuth(HomeAssistantError):
    """Error to indicate there is invalid auth."""
